Workbook

Sheet 単語入力
A1: 番号 | B1: 単語 | C1: 意味
A2: 1 | B2: less | C2: より少ない,より少なく
A3: 2 | B3: receive | C3: ～を受け取る
A4: 3 | B4: myself | C4: 私自身（を,に）
A5: 4 | B5: order | C5: 注文,命令, 注文する,命じる
A6: 5 | B6: seven | C6: ７,７つの
A7: 6 | B7: lake | C7: 湖
A8: 7 | B8: lie | C8: 横たわる,嘘をつく,嘘
A9: 8 | B9: worker | C9: 働くひと,労働者
A10: 9 | B10: concert | C10: コンサート
A11: 10 | B11: outside | C11: 外側に,～の外側に,外側
A12: 11 | B12: hall | C12: 会館,（広い）玄関
A13: 12 | B13: spring | C13: 春,泉
... A301: 300 | B301: fresh | C301: 新鮮な
A302: 301
A303: 302
A304: 303
A305: 304
A306: 305
A307: 306
A308: 307
A309: 308
A310: 309
A311: 310
A312: 311
A313: 312
... A315: 314

Sheet 作成シート
C1: =単語入力!A1 -> 番号 | D1: =単語入力!B1 -> 単語 | E1: =単語入力!C1 -> 意味 | F1: 問題はじめ | G1: 2 | H1: 1 | I1: =VLOOKUP(H1,$B$2:$E$999,3+$G$3,FALSE) -> hit | J1: =VLOOKUP(H1,$B$2:$E$999,4+$G$3,FALSE) -> (~を)打つ,ひと打ち,成功
A2: =RAND() -> 0.3315234 | B2: =RANK(A2,OFFSET($A$2,$G$1-2,0,$G$2-$G$1+1)) -> 32 | C2: =単語入力!A2 -> 1 | D2: =単語入力!B2 -> less | E2: =単語入力!C2 -> より少ない,より少なく | F2: 問題終わり | G2: 51 | H2: 2 | I2: =VLOOKUP(H2,$B$2:$E$999,3+$G$3,FALSE) -> shall | J2: =VLOOKUP(H2,$B$2:$E$999,4+$G$3,FALSE) -> (Shall I~?で)しましょうか, (Shall we~?で)しませんか
A3: =RAND() -> 0.64049827 | B3: =RANK(A3,OFFSET($A$2,$G$1-2,0,$G$2-$G$1+1)) -> 12 | C3: =単語入力!A3 -> 2 | D3: =単語入力!B3 -> receive | E3: =単語入力!C3 -> ～を受け取る | F3: 問題パターン | G3: 0 | H3: 3 | I3: =VLOOKUP(H3,$B$2:$E$999,3+$G$3,FALSE) -> else | J3: =VLOOKUP(H3,$B$2:$E$999,4+$G$3,FALSE) -> そのほかに
A4: =RAND() -> 0.86199031 | B4: =RANK(A4,OFFSET($A$2,$G$1-2,0,$G$2-$G$1+1)) -> 7 | C4: =単語入力!A4 -> 3 | D4: =単語入力!B4 -> myself | E4: =単語入力!C4 -> 私自身（を,に） | H4: 4 | I4: =VLOOKUP(H4,$B$2:$E$999,3+$G$3,FALSE) -> design | J4: =VLOOKUP(H4,$B$2:$E$999,4+$G$3,FALSE) -> 設計,デザイン, （～を）設計する
A5: =RAND() -> 0.43498382 | B5: =RANK(A5,OFFSET($A$2,$G$1-2,0,$G$2-$G$1+1)) -> 23 | C5: =単語入力!A5 -> 4 | D5: =単語入力!B5 -> order | E5: =単語入力!C5 -> 注文,命令, 注文する,命じる | H5: 5 | I5: =VLOOKUP(H5,$B$2:$E$999,3+$G$3,FALSE) -> gold | J5: =VLOOKUP(H5,$B$2:$E$999,4+$G$3,FALSE) -> 金,金製の
A6: =RAND() -> 0.61480051 | B6: =RANK(A6,OFFSET($A$2,$G$1-2,0,$G$2-$G$1+1)) -> 15 | C6: =単語入力!A6 -> 5 | D6: =単語入力!B6 -> seven | E6: =単語入力!C6 -> ７,７つの | H6: 6 | I6: =VLOOKUP(H6,$B$2:$E$999,3+$G$3,FALSE) -> technology | J6: =VLOOKUP(H6,$B$2:$E$999,4+$G$3,FALSE) -> 科学技術
A7: =RAND() -> 0.50981693 | B7: =RANK(A7,OFFSET($A$2,$G$1-2,0,$G$2-$G$1+1)) -> 20 | C7: =単語入力!A7 -> 6 | D7: =単語入力!B7 -> lake | E7: =単語入力!C7 -> 湖 | H7: 7 | I7: =VLOOKUP(H7,$B$2:$E$999,3+$G$3,FALSE) -> myself | J7: =VLOOKUP(H7,$B$2:$E$999,4+$G$3,FALSE) -> 私自身（を,に）
A8: =RAND() -> 0.0013890713 | B8: =RANK(A8,OFFSET($A$2,$G$1-2,0,$G$2-$G$1+1)) -> 50 | C8: =単語入力!A8 -> 7 | D8: =単語入力!B8 -> lie | E8: =単語入力!C8 -> 横たわる,嘘をつく,嘘 | H8: 8 | I8: =VLOOKUP(H8,$B$2:$E$999,3+$G$3,FALSE) -> hall | J8: =VLOOKUP(H8,$B$2:$E$999,4+$G$3,FALSE) -> 会館,（広い）玄関
A9: =RAND() -> 0.30774836 | B9: =RANK(A9,OFFSET($A$2,$G$1-2,0,$G$2-$G$1+1)) -> 35 | C9: =単語入力!A9 -> 8 | D9: =単語入力!B9 -> worker | E9: =単語入力!C9 -> 働くひと,労働者 | H9: 9 | I9: =VLOOKUP(H9,$B$2:$E$999,3+$G$3,FALSE) -> head | J9: =VLOOKUP(H9,$B$2:$E$999,4+$G$3,FALSE) -> 頭,長
A10: =RAND() -> 0.025958899 | B10: =RANK(A10,OFFSET($A$2,$G$1-2,0,$G$2-$G$1+1)) -> 47 | C10: =単語入力!A10 -> 9 | D10: =単語入力!B10 -> concert | E10: =単語入力!C10 -> コンサート | H10: 10 | I10: =VLOOKUP(H10,$B$2:$E$999,3+$G$3,FALSE) -> seem | J10: =VLOOKUP(H10,$B$2:$E$999,4+$G$3,FALSE) -> ～のように思われる （見える）
A11: =RAND() -> 0.55095993 | B11: =RANK(A11,OFFSET($A$2,$G$1-2,0,$G$2-$G$1+1)) -> 17 | C11: =単語入力!A11 -> 10 | D11: =単語入力!B11 -> outside | E11: =単語入力!C11 -> 外側に,～の外側に,外側 | H11: 11 | I11: =VLOOKUP(H11,$B$2:$E$999,3+$G$3,FALSE) -> spring | J11: =VLOOKUP(H11,$B$2:$E$999,4+$G$3,FALSE) -> 春,泉
A12: =RAND() -> 0.83894199 | B12: =RANK(A12,OFFSET($A$2,$G$1-2,0,$G$2-$G$1+1)) -> 8 | C12: =単語入力!A12 -> 11 | D12: =単語入力!B12 -> hall | E12: =単語入力!C12 -> 会館,（広い）玄関 | H12: 12 | I12: =VLOOKUP(H12,$B$2:$E$999,3+$G$3,FALSE) -> receive | J12: =VLOOKUP(H12,$B$2:$E$999,4+$G$3,FALSE) -> ～を受け取る
A13: =RAND() -> 0.66440037 | B13: =RANK(A13,OFFSET($A$2,$G$1-2,0,$G$2-$G$1+1)) -> 11 | C13: =単語入力!A13 -> 12 | D13: =単語入力!B13 -> spring | E13: =単語入力!C13 -> 春,泉 | H13: 13 | I13: =VLOOKUP(H13,$B$2:$E$999,3+$G$3,FALSE) -> seat | J13: =VLOOKUP(H13,$B$2:$E$999,4+$G$3,FALSE) -> 座席
A14: =RAND() -> 0.55011881 | B14: =RANK(A14,OFFSET($A$2,$G$1-2,0,$G$2-$G$1+1)) -> 18 | C14: =単語入力!A14 -> 13 | D14: =単語入力!B14 -> card | E14: =単語入力!C14 -> カード,トランプ | H14: 14 | I14: =VLOOKUP(H14,$B$2:$E$999,3+$G$3,FALSE) -> visitor | J14: =VLOOKUP(H14,$B$2:$E$999,4+$G$3,FALSE) -> 訪問者
A15: =RAND() -> 0.33524052 | B15: =RANK(A15,OFFSET($A$2,$G$1-2,0,$G$2-$G$1+1)) -> 31 | C15: =単語入力!A15 -> 14 | D15: =単語入力!B15 -> gift | E15: =単語入力!C15 -> 贈り物 | H15: 15 | I15: =VLOOKUP(H15,$B$2:$E$999,3+$G$3,FALSE) -> seven | J15: =VLOOKUP(H15,$B$2:$E$999,4+$G$3,FALSE) -> ７,７つの
... A20: =RAND() -> 0.13705105 | B20: =RANK(A20,OFFSET($A$2,$G$1-2,0,$G$2-$G$1+1)) -> 42 | C20: =単語入力!A20 -> 19 | D20: =単語入力!B20 -> fruit | E20: =単語入力!C20 -> 果物 | H20: 20 | I20: =VLOOKUP(H20,$B$2:$E$999,3+$G$3,FALSE) -> lake | J20: =VLOOKUP(H20,$B$2:$E$999,4+$G$3,FALSE) -> 湖
A21: =RAND() -> 0.42693903 | B21: =RANK(A21,OFFSET($A$2,$G$1-2,0,$G$2-$G$1+1)) -> 25 | C21: =単語入力!A21 -> 20 | D21: =単語入力!B21 -> among | E21: =単語入力!C21 -> (３つ以上のもの)の間に(で)
A22: =RAND() -> 0.01235052 | B22: =RANK(A22,OFFSET($A$2,$G$1-2,0,$G$2-$G$1+1)) -> 49 | C22: =単語入力!A22 -> 21 | D22: =単語入力!B22 -> age | E22: =単語入力!C22 -> 年齢,時代
A23: =RAND() -> 0.96294367 | B23: =RANK(A23,OFFSET($A$2,$G$1-2,0,$G$2-$G$1+1)) -> 2 | C23: =単語入力!A23 -> 22 | D23: =単語入力!B23 -> shall | E23: =単語入力!C23 -> (Shall I~?で)しましょうか, (Shall we~?で)しませんか
A24: =RAND() -> 0.43160829 | B24: =RANK(A24,OFFSET($A$2,$G$1-2,0,$G$2-$G$1+1)) -> 24 | C24: =単語入力!A24 -> 23 | D24: =単語入力!B24 -> health | E24: =単語入力!C24 -> 健康
A25: =RAND() -> 0.12239132 | B25: =RANK(A25,OFFSET($A$2,$G$1-2,0,$G$2-$G$1+1)) -> 43 | C25: =単語入力!A25 -> 24 | D25: =単語入力!B25 -> ground | E25: =単語入力!C25 -> 地面,運動場
A26: =RAND() -> 0.55641856 | B26: =RANK(A26,OFFSET($A$2,$G$1-2,0,$G$2-$G$1+1)) -> 16 | C26: =単語入力!A26 -> 25 | D26: =単語入力!B26 -> medicine | E26: =単語入力!C26 -> 薬,医学
A27: =RAND() -> 0.34509186 | B27: =RANK(A27,OFFSET($A$2,$G$1-2,0,$G$2-$G$1+1)) -> 30 | C27: =単語入力!A27 -> 26 | D27: =単語入力!B27 -> piano | E27: =単語入力!C27 -> ピアノ
A28: =RAND() -> 0.1462476 | B28: =RANK(A28,OFFSET($A$2,$G$1-2,0,$G$2-$G$1+1)) -> 40 | C28: =単語入力!A28 -> 27 | D28: =単語入力!B28 -> collect | E28: =単語入力!C28 -> ～を集める
A29: =RAND() -> 0.23845199 | B29: =RANK(A29,OFFSET($A$2,$G$1-2,0,$G$2-$G$1+1)) -> 37 | C29: =単語入力!A29 -> 28 | D29: =単語入力!B29 -> strange | E29: =単語入力!C29 -> 奇妙な,不思議な
A30: =RAND() -> 0.88762197 | B30: =RANK(A30,OFFSET($A$2,$G$1-2,0,$G$2-$G$1+1)) -> 6 | C30: =単語入力!A30 -> 29 | D30: =単語入力!B30 -> technology | E30: =単語入力!C30 -> 科学技術
A31: =RAND() -> 0.23262366 | B31: =RANK(A31,OFFSET($A$2,$G$1-2,0,$G$2-$G$1+1)) -> 38 | C31: =単語入力!A31 -> 30 | D31: =単語入力!B31 -> eight | E31: =単語入力!C31 -> ８つの,８
A32: =RAND() -> 0.73243292 | B32: =RANK(A32,OFFSET($A$2,$G$1-2,0,$G$2-$G$1+1)) -> 10 | C32: =単語入力!A32 -> 31 | D32: =単語入力!B32 -> seem | E32: =単語入力!C32 -> ～のように思われる （見える）
... A62: =RAND() -> 0.60683236 | B62: =RANK(A62,OFFSET($A$2,$G$1-2,0,$G$2-$G$1+1)) -> #N/A | C62: =単語入力!A62 -> 61 | D62: =単語入力!B62 -> piece | E62: =単語入力!C62 -> １個[枚,片]
C63: =単語入力!A63 -> 62 | D63: =単語入力!B63 -> Friday | E63: =単語入力!C63 -> 金曜日
C64: =単語入力!A64 -> 63 | D64: =単語入力!B64 -> grandma | E64: =単語入力!C64 -> おばあちゃん
C65: =単語入力!A65 -> 64 | D65: =単語入力!B65 -> coffee | E65: =単語入力!C65 -> コーヒー
C66: =単語入力!A66 -> 65 | D66: =単語入力!B66 -> several | E66: =単語入力!C66 -> いくつかの,数人(個)の
C67: =単語入力!A67 -> 66 | D67: =単語入力!B67 -> especially | E67: =単語入力!C67 -> 特に
C68: =単語入力!A68 -> 67 | D68: =単語入力!B68 -> milk | E68: =単語入力!C68 -> 牛乳,ミルク
C69: =単語入力!A69 -> 68 | D69: =単語入力!B69 -> product | E69: =単語入力!C69 -> 製品,生産物
C70: =単語入力!A70 -> 69 | D70: =単語入力!B70 -> zoo | E70: =単語入力!C70 -> 動物園
C71: =単語入力!A71 -> 70 | D71: =単語入力!B71 -> unkle | E71: =単語入力!C71 -> おじ
C72: =単語入力!A72 -> 71 | D72: =単語入力!B72 -> century | E72: =単語入力!C72 -> 世紀,１００年
C73: =単語入力!A73 -> 72 | D73: =単語入力!B73 -> floor | E73: =単語入力!C73 -> 床,階
...

Sheet 出力シート
A1: 単語 | B1: 意味
A2: less | B2: より少ない,より少なく
A3: receive | B3: ～を受け取る | D3: 名前
A4: myself | B4: 私自身（を,に）
A5: order | B5: 注文,命令, 注文する,命じる | C5: 単語 | D5: 意味 | E5: 解答
A6: seven | B6: ７,７つの | C6: =作成シート!I1 -> hit | E6: =作成シート!J1 -> (~を)打つ,ひと打ち,成功
A7: lake | B7: 湖 | C7: =作成シート!I2 -> shall | E7: =作成シート!J2 -> (Shall I~?で)しましょうか, (Shall we~?で)しませんか
A8: lie | B8: 横たわる,嘘をつく,嘘 | C8: =作成シート!I3 -> else | E8: =作成シート!J3 -> そのほかに
A9: worker | B9: 働くひと,労働者 | C9: =作成シート!I4 -> design | E9: =作成シート!J4 -> 設計,デザイン, （～を）設計する
A10: concert | B10: コンサート | C10: =作成シート!I5 -> gold | E10: =作成シート!J5 -> 金,金製の
A11: outside | B11: 外側に,～の外側に,外側 | C11: =作成シート!I6 -> technology | E11: =作成シート!J6 -> 科学技術
A12: hall | B12: 会館,（広い）玄関 | C12: =作成シート!I7 -> myself | E12: =作成シート!J7 -> 私自身（を,に）
A13: spring | B13: 春,泉 | C13: =作成シート!I8 -> hall | E13: =作成シート!J8 -> 会館,（広い）玄関
A14: card | B14: カード,トランプ | C14: =作成シート!I9 -> head | E14: =作成シート!J9 -> 頭,長
A15: gift | B15: 贈り物 | C15: =作成シート!I10 -> seem | E15: =作成シート!J10 -> ～のように思われる （見える）
A16: type | B16: 型,種類,タイプ | C16: =作成シート!I11 -> spring | E16: =作成シート!J11 -> 春,泉
A17: born | B17: (be bornで)生まれる | C17: =作成シート!I12 -> receive | E17: =作成シート!J12 -> ～を受け取る
... A25: ground | B25: 地面,運動場 | C25: =作成シート!I20 -> lake | E25: =作成シート!J20 -> 湖
A26: medicine | B26: 薬,医学
A27: piano | B27: ピアノ
A28: collect | B28: ～を集める
A29: strange | B29: 奇妙な,不思議な
A30: technology | B30: 科学技術
A31: eight | B31: ８つの,８
A32: seem | B32: ～のように思われる （見える）
A33: hit | B33: (~を)打つ,ひと打ち,成功
A34: side | B34: 側,側面
A35: New York | B35: ニューヨーク
A36: dictionary | B36: 辞書
A37: seat | B37: 座席
... A161: full | B161: いっぱいの 満腹の,完全な
